Workbook

Sheet README
A1: GPO Community Value List Template (Google Sheets-ready)
A3: What this workbook does
A4: - Maintain a master item list in the Items sheet. - Collect community trade reports in Trade_Reports. - Items auto-calculates values using APPROVED trades within windows set in Settings. - Weighted median uses Effective_Weight (trust + recency + proof).
A6: Quick start
A7: 1) Add items on Items (columns A–E). Leave F–L to calculate. 2) Add trade reports on Trade_Reports (row 3+). Verify proof, then set Approved_Status = APPROVED. 3) Check Items for Final_Value_Point, Trend, Confidence, Sample_Size. 4) Need more rows? Copy the last row down (Items up to 300, Trade_Reports up to 500).
A9: Change log
A10: Fixed demanded 5.0
A11: 5.1 -changed file to google sheet

Sheet Test for bot
A1: 2026-01-31T19:06:25.058Z | B1: hello from discord bot
A2: 2026-01-31T19:23:01.226Z | B2: hello from discord bot
A3: 2026-01-31T19:48:02.679Z | B3: hello from discord bot

Sheet Settings
A1: Settings
A3: Value windows (days)
A4: Window_7d | B4: 30
A5: Window_30d | B5: 60
A7: Recency multipliers (by age in days) | E7: Trust level multipliers
A8: Age <= | B8: 3 | C8: 2 | E8: New | F8: 0.5
A9: Age <= | B9: 7 | C9: 1.5 | E9: Regular | F9: 1
A10: Age <= | B10: 14 | C10: 1.25 | E10: Trusted | F10: 1.5
A11: Age <= | B11: 30 | C11: 0.7 | E11: Flagged | F11: 0
A12: Else | C12: 0.6
A14: Minimum sample size for auto-value | B14: 1
A16: Proof multiplier when Proof_URL missing | B16: 1 | C16: WIP
A18: Trend threshold (relative change) | B18: 0.05

Sheet Lists
A1: Categories | B1: Rarity_Tier | C1: Unit_Anchor | D1: Trend | E1: Publish | F1: Approved_Status | G1: Trust_Level | H1: Demand_Level
A2: Fruit | B2: Common | C2: POINT | D2: UP | E2: YES | F2: PENDING | G2: New | H2: LOW
A3: Weapon | B3: Uncommon | D3: STABLE | E3: NO | F3: APPROVED | G3: Regular | H3: MID
A4: Armor | B4: Rare | D4: DOWN | F4: REJECTED | G4: Trusted | H4: HIGH
A5: Accessory | B5: Epic | G5: Flagged
A6: Currency | B6: Legendary
A7: Ship | B7: Mythic
A8: Misc | B8: Limited
B9: Event

Sheet Items
A1: ITEMS
A2: Item_ID | B2: Item_Name | C2: Category | D2: Rarity/Tier | E2: Unit_Anchor | F2: Final_Value_Point | G2: Value_Low | H2: Value_High | I2: Trend | J2: Confidence_% | K2: Sample_Size | L2: Last_Updated | M2: Publish? | N2: Notes | O2: Demand | P2: TotalWeight_7d | Q2: TotalWeight_30d | R2: WM_30d | S2: Sample_30d | T2: Min_7d | U2: Max_7d | V2: Avg_Demand | W2: Demand_Line
A3: FRUIT_GOMU | B3: Gomu | C3: Fruit | D3: Legendary | E3: POINT | F3: =IF($A3="","",IF($K3<Settings!$B$14,"",IF($P3=0,"",IFERROR(_xludf.MINIFS(Trade_Reports!$I$3:$I$502,Trade_Reports!$H$3:$H$502,$A3,Trade_Reports!$M$3:$M$502,"APPROVED",Trade_Reports!$Q$3:$Q$502,"<="&Settings!$B$4,Trade_Reports!$W$3:$W$502,">="&0.5*$P3),"")))) | G3: =IF($A3="","",IF($K3=0,"",IFERROR(_xludf.MINIFS(Trade_Reports!$I$3:$I$502,Trade_Reports!$H$3:$H$502,$A3,Trade_Reports!$M$3:$M$502,"APPROVED",Trade_Reports!$Q$3:$Q$502,"<="&Settings!$B$4),""))) | H3: =IF($A3="","",IF($K3=0,"",IFERROR(_xludf.MAXIFS(Trade_Reports!$I$3:$I$502,Trade_Reports!$H$3:$H$502,$A3,Trade_Reports!$M$3:$M$502,"APPROVED",Trade_Reports!$Q$3:$Q$502,"<="&Settings!$B$4),""))) | I3: =IF($A3="","",IF($F3="","",IF($Q3="","",IF(ABS($F3-$Q3)/$Q3<=Settings!$B$18,"STABLE",IF($F3>$Q3,"UP","DOWN"))))) | J3: =IF($A3="","",IF($K3=0,"",MIN(1,ROUND($K3/Settings!$B$14,2)))) -> 1 | K3: =IF($A3="","",COUNTIFS(Trade_Reports!$H$3:$H$502,$A3,Trade_Reports!$M$3:$M$502,"APPROVED",Trade_Reports!$Q$3:$Q$502,"<="&Settings!$B$4)) -> 2 | L3: =IF($A3="","",IF($K3=0,"",IFERROR(_xludf.MAXIFS(Trade_Reports!$O$3:$O$502,Trade_Reports!$H$3:$H$502,$A3,Trade_Reports!$M$3:$M$502,"APPROVED"),""))) | M3: NO | O3: =IF(OR($A3="",ISERROR(SEARCH("_",$A3))),"", $W3) -> LOW | P3: =IF($A3="","",SUMIFS(Trade_Reports!$U$3:$U$502,Trade_Reports!$H$3:$H$502,$A3,Trade_Reports!$M$3:$M$502,"APPROVED",Trade_Reports!$Q$3:$Q$502,"<="&Settings!$B$4)) -> 2.1 | Q3: =IF($A3="","",SUMIFS(Trade_Reports!$U$3:$U$502,Trade_Reports!$H$3:$H$502,$A3,Trade_Reports!$M$3:$M$502,"APPROVED",Trade_Reports!$Q$3:$Q$502,"<="&Settings!$B$5)) -> 3.9 | R3: =IF($A3="","",IF($Q3=0,"",IFERROR(_xludf.MINIFS(Trade_Reports!$I$3:$I$502,Trade_Reports!$H$3:$H$502,$A3,Trade_Reports!$M$3:$M$502,"APPROVED",Trade_Reports!$Q$3:$Q$502,"<="&Settings!$B$5,Trade_Reports!$X$3:$X$502,">="&0.5*$Q3),""))) | S3: =IF($A3="","",COUNTIFS(Trade_Reports!$H$3:$H$502,$A3,Trade_Reports!$M$3:$M$502,"APPROVED",Trade_Reports!$Q$3:$Q$502,"<="&Settings!$B$5)) -> 4 | V3: =IF(OR($A3="",ISERROR(SEARCH("_",$A3))),"",IFERROR(SUMIFS(Trade_Reports!$Z$3:$Z$502,Trade_Reports!$H$3:$H$502,$A3,Trade_Reports!$M$3:$M$502,"APPROVED")/SUMIFS(Trade_Reports!$U$3:$U$502,Trade_Reports!$H$3:$H$502,$A3,Trade_Reports!$M$3:$M$502,"APPROVED"),"")) -> 0.80769231 | W3: =IF($V3="","",IF($V3<1.75,"LOW",IF($V3<2.5,"MID","HIGH"))) -> LOW
A4: WEAPON_BISENTO | B4: Bisento | C4: Weapon | D4: Mythic | E4: POINT | F4: =IF($A4="","",IF($K4<Settings!$B$14,"",IF($P4=0,"",IFERROR(_xludf.MINIFS(Trade_Reports!$I$3:$I$502,Trade_Reports!$H$3:$H$502,$A4,Trade_Reports!$M$3:$M$502,"APPROVED",Trade_Reports!$Q$3:$Q$502,"<="&Settings!$B$4,Trade_Reports!$W$3:$W$502,">="&0.5*$P4),"")))) | G4: =IF($A4="","",IF($K4=0,"",IFERROR(_xludf.MINIFS(Trade_Reports!$I$3:$I$502,Trade_Reports!$H$3:$H$502,$A4,Trade_Reports!$M$3:$M$502,"APPROVED",Trade_Reports!$Q$3:$Q$502,"<="&Settings!$B$4),""))) | H4: =IF($A4="","",IF($K4=0,"",IFERROR(_xludf.MAXIFS(Trade_Reports!$I$3:$I$502,Trade_Reports!$H$3:$H$502,$A4,Trade_Reports!$M$3:$M$502,"APPROVED",Trade_Reports!$Q$3:$Q$502,"<="&Settings!$B$4),""))) | I4: =IF($A4="","",IF($F4="","",IF($Q4="","",IF(ABS($F4-$Q4)/$Q4<=Settings!$B$18,"STABLE",IF($F4>$Q4,"UP","DOWN"))))) | J4: =IF($A4="","",IF($K4=0,"",MIN(1,ROUND($K4/Settings!$B$14,2)))) -> 1 | K4: =IF($A4="","",COUNTIFS(Trade_Reports!$H$3:$H$502,$A4,Trade_Reports!$M$3:$M$502,"APPROVED",Trade_Reports!$Q$3:$Q$502,"<="&Settings!$B$4)) -> 1 | L4: =IF($A4="","",IF($K4=0,"",IFERROR(_xludf.MAXIFS(Trade_Reports!$O$3:$O$502,Trade_Reports!$H$3:$H$502,$A4,Trade_Reports!$M$3:$M$502,"APPROVED"),""))) | M4: NO | O4: =IF(OR($A4="",ISERROR(SEARCH("_",$A4))),"", $W4) -> HIGH | P4: =IF($A4="","",SUMIFS(Trade_Reports!$U$3:$U$502,Trade_Reports!$H$3:$H$502,$A4,Trade_Reports!$M$3:$M$502,"APPROVED",Trade_Reports!$Q$3:$Q$502,"<="&Settings!$B$4)) -> 1.05 | Q4: =IF($A4="","",SUMIFS(Trade_Reports!$U$3:$U$502,Trade_Reports!$H$3:$H$502,$A4,Trade_Reports!$M$3:$M$502,"APPROVED",Trade_Reports!$Q$3:$Q$502,"<="&Settings!$B$5)) -> 1.95 | R4: =IF($A4="","",IF($Q4=0,"",IFERROR(_xludf.MINIFS(Trade_Reports!$I$3:$I$502,Trade_Reports!$H$3:$H$502,$A4,Trade_Reports!$M$3:$M$502,"APPROVED",Trade_Reports!$Q$3:$Q$502,"<="&Settings!$B$5,Trade_Reports!$X$3:$X$502,">="&0.5*$Q4),""))) | S4: =IF($A4="","",COUNTIFS(Trade_Reports!$H$3:$H$502,$A4,Trade_Reports!$M$3:$M$502,"APPROVED",Trade_Reports!$Q$3:$Q$502,"<="&Settings!$B$5)) -> 2 | V4: =IF(OR($A4="",ISERROR(SEARCH("_",$A4))),"",IFERROR(SUMIFS(Trade_Reports!$Z$3:$Z$502,Trade_Reports!$H$3:$H$502,$A4,Trade_Reports!$M$3:$M$502,"APPROVED")/SUMIFS(Trade_Reports!$U$3:$U$502,Trade_Reports!$H$3:$H$502,$A4,Trade_Reports!$M$3:$M$502,"APPROVED"),"")) -> 3 | W4: =IF($V4="","",IF($V4<1.75,"LOW",IF($V4<2.5,"MID","HIGH"))) -> HIGH
A5: Fruits | F5: =IF($A5="","",IF($K5<Settings!$B$14,"",IF($P5=0,"",IFERROR(_xludf.MINIFS(Trade_Reports!$I$3:$I$502,Trade_Reports!$H$3:$H$502,$A5,Trade_Reports!$M$3:$M$502,"APPROVED",Trade_Reports!$Q$3:$Q$502,"<="&Settings!$B$4,Trade_Reports!$W$3:$W$502,">="&0.5*$P5),"")))) | G5: =IF($A5="","",IF($K5=0,"",IFERROR(_xludf.MINIFS(Trade_Reports!$I$3:$I$502,Trade_Reports!$H$3:$H$502,$A5,Trade_Reports!$M$3:$M$502,"APPROVED",Trade_Reports!$Q$3:$Q$502,"<="&Settings!$B$4),""))) | H5: =IF($A5="","",IF($K5=0,"",IFERROR(_xludf.MAXIFS(Trade_Reports!$I$3:$I$502,Trade_Reports!$H$3:$H$502,$A5,Trade_Reports!$M$3:$M$502,"APPROVED",Trade_Reports!$Q$3:$Q$502,"<="&Settings!$B$4),""))) | I5: =IF($A5="","",IF($F5="","",IF($Q5="","",IF(ABS($F5-$Q5)/$Q5<=Settings!$B$18,"STABLE",IF($F5>$Q5,"UP","DOWN"))))) | J5: =IF($A5="","",IF($K5=0,"",MIN(1,ROUND($K5/Settings!$B$14,2)))) | K5: =IF($A5="","",COUNTIFS(Trade_Reports!$H$3:$H$502,$A5,Trade_Reports!$M$3:$M$502,"APPROVED",Trade_Reports!$Q$3:$Q$502,"<="&Settings!$B$4)) -> 0 | L5: =IF($A5="","",IF($K5=0,"",IFERROR(_xludf.MAXIFS(Trade_Reports!$O$3:$O$502,Trade_Reports!$H$3:$H$502,$A5,Trade_Reports!$M$3:$M$502,"APPROVED"),""))) | M5: NO | O5: =IF(OR($A5="",ISERROR(SEARCH("_",$A5))),"", $W5) | P5: =IF($A5="","",SUMIFS(Trade_Reports!$U$3:$U$502,Trade_Reports!$H$3:$H$502,$A5,Trade_Reports!$M$3:$M$502,"APPROVED",Trade_Reports!$Q$3:$Q$502,"<="&Settings!$B$4)) -> 0 | Q5: =IF($A5="","",SUMIFS(Trade_Reports!$U$3:$U$502,Trade_Reports!$H$3:$H$502,$A5,Trade_Reports!$M$3:$M$502,"APPROVED",Trade_Reports!$Q$3:$Q$502,"<="&Settings!$B$5)) -> 0 | R5: =IF($A5="","",IF($Q5=0,"",IFERROR(_xludf.MINIFS(Trade_Reports!$I$3:$I$502,Trade_Reports!$H$3:$H$502,$A5,Trade_Reports!$M$3:$M$502,"APPROVED",Trade_Reports!$Q$3:$Q$502,"<="&Settings!$B$5,Trade_Reports!$X$3:$X$502,">="&0.5*$Q5),""))) | S5: =IF($A5="","",COUNTIFS(Trade_Reports!$H$3:$H$502,$A5,Trade_Reports!$M$3:$M$502,"APPROVED",Trade_Reports!$Q$3:$Q$502,"<="&Settings!$B$5)) -> 0 | V5: =IF(OR($A5="",ISERROR(SEARCH("_",$A5))),"",IFERROR(SUMIFS(Trade_Reports!$Z$3:$Z$502,Trade_Reports!$H$3:$H$502,$A5,Trade_Reports!$M$3:$M$502,"APPROVED")/SUMIFS(Trade_Reports!$U$3:$U$502,Trade_Reports!$H$3:$H$502,$A5,Trade_Reports!$M$3:$M$502,"APPROVED"),"")) | W5: =IF($V5="","",IF($V5<1.75,"LOW",IF($V5<2.5,"MID","HIGH")))
A6: FRUIT_ITO | F6: =IF($A6="","",IF($K6<Settings!$B$14,"",IF($P6=0,"",IFERROR(_xludf.MINIFS(Trade_Reports!$I$3:$I$502,Trade_Reports!$H$3:$H$502,$A6,Trade_Reports!$M$3:$M$502,"APPROVED",Trade_Reports!$Q$3:$Q$502,"<="&Settings!$B$4,Trade_Reports!$W$3:$W$502,">="&0.5*$P6),"")))) | G6: =IF($A6="","",IF($K6=0,"",IFERROR(_xludf.MINIFS(Trade_Reports!$I$3:$I$502,Trade_Reports!$H$3:$H$502,$A6,Trade_Reports!$M$3:$M$502,"APPROVED",Trade_Reports!$Q$3:$Q$502,"<="&Settings!$B$4),""))) | H6: =IF($A6="","",IF($K6=0,"",IFERROR(_xludf.MAXIFS(Trade_Reports!$I$3:$I$502,Trade_Reports!$H$3:$H$502,$A6,Trade_Reports!$M$3:$M$502,"APPROVED",Trade_Reports!$Q$3:$Q$502,"<="&Settings!$B$4),""))) | I6: =IF($A6="","",IF($F6="","",IF($Q6="","",IF(ABS($F6-$Q6)/$Q6<=Settings!$B$18,"STABLE",IF($F6>$Q6,"UP","DOWN"))))) | J6: =IF($A6="","",IF($K6=0,"",MIN(1,ROUND($K6/Settings!$B$14,2)))) | K6: =IF($A6="","",COUNTIFS(Trade_Reports!$H$3:$H$502,$A6,Trade_Reports!$M$3:$M$502,"APPROVED",Trade_Reports!$Q$3:$Q$502,"<="&Settings!$B$4)) -> 0 | L6: =IF($A6="","",IF($K6=0,"",IFERROR(_xludf.MAXIFS(Trade_Reports!$O$3:$O$502,Trade_Reports!$H$3:$H$502,$A6,Trade_Reports!$M$3:$M$502,"APPROVED"),""))) | M6: NO | O6: =IF(OR($A6="",ISERROR(SEARCH("_",$A6))),"", $W6) | P6: =IF($A6="","",SUMIFS(Trade_Reports!$U$3:$U$502,Trade_Reports!$H$3:$H$502,$A6,Trade_Reports!$M$3:$M$502,"APPROVED",Trade_Reports!$Q$3:$Q$502,"<="&Settings!$B$4)) -> 0 | Q6: =IF($A6="","",SUMIFS(Trade_Reports!$U$3:$U$502,Trade_Reports!$H$3:$H$502,$A6,Trade_Reports!$M$3:$M$502,"APPROVED",Trade_Reports!$Q$3:$Q$502,"<="&Settings!$B$5)) -> 0 | R6: =IF($A6="","",IF($Q6=0,"",IFERROR(_xludf.MINIFS(Trade_Reports!$I$3:$I$502,Trade_Reports!$H$3:$H$502,$A6,Trade_Reports!$M$3:$M$502,"APPROVED",Trade_Reports!$Q$3:$Q$502,"<="&Settings!$B$5,Trade_Reports!$X$3:$X$502,">="&0.5*$Q6),""))) | S6: =IF($A6="","",COUNTIFS(Trade_Reports!$H$3:$H$502,$A6,Trade_Reports!$M$3:$M$502,"APPROVED",Trade_Reports!$Q$3:$Q$502,"<="&Settings!$B$5)) -> 0 | V6: =IF(OR($A6="",ISERROR(SEARCH("_",$A6))),"",IFERROR(SUMIFS(Trade_Reports!$Z$3:$Z$502,Trade_Reports!$H$3:$H$502,$A6,Trade_Reports!$M$3:$M$502,"APPROVED")/SUMIFS(Trade_Reports!$U$3:$U$502,Trade_Reports!$H$3:$H$502,$A6,Trade_Reports!$M$3:$M$502,"APPROVED"),"")) | W6: =IF($V6="","",IF($V6<1.75,"LOW",IF($V6<2.5,"MID","HIGH")))
A7: FRUIT_PAW | F7: =IF($A7="","",IF($K7<Settings!$B$14,"",IF($P7=0,"",IFERROR(_xludf.MINIFS(Trade_Reports!$I$3:$I$502,Trade_Reports!$H$3:$H$502,$A7,Trade_Reports!$M$3:$M$502,"APPROVED",Trade_Reports!$Q$3:$Q$502,"<="&Settings!$B$4,Trade_Reports!$W$3:$W$502,">="&0.5*$P7),"")))) | G7: =IF($A7="","",IF($K7=0,"",IFERROR(_xludf.MINIFS(Trade_Reports!$I$3:$I$502,Trade_Reports!$H$3:$H$502,$A7,Trade_Reports!$M$3:$M$502,"APPROVED",Trade_Reports!$Q$3:$Q$502,"<="&Settings!$B$4),""))) | H7: =IF($A7="","",IF($K7=0,"",IFERROR(_xludf.MAXIFS(Trade_Reports!$I$3:$I$502,Trade_Reports!$H$3:$H$502,$A7,Trade_Reports!$M$3:$M$502,"APPROVED",Trade_Reports!$Q$3:$Q$502,"<="&Settings!$B$4),""))) | I7: =IF($A7="","",IF($F7="","",IF($Q7="","",IF(ABS($F7-$Q7)/$Q7<=Settings!$B$18,"STABLE",IF($F7>$Q7,"UP","DOWN"))))) | J7: =IF($A7="","",IF($K7=0,"",MIN(1,ROUND($K7/Settings!$B$14,2)))) | K7: =IF($A7="","",COUNTIFS(Trade_Reports!$H$3:$H$502,$A7,Trade_Reports!$M$3:$M$502,"APPROVED",Trade_Reports!$Q$3:$Q$502,"<="&Settings!$B$4)) -> 0 | L7: =IF($A7="","",IF($K7=0,"",IFERROR(_xludf.MAXIFS(Trade_Reports!$O$3:$O$502,Trade_Reports!$H$3:$H$502,$A7,Trade_Reports!$M$3:$M$502,"APPROVED"),""))) | M7: NO | O7: =IF(OR($A7="",ISERROR(SEARCH("_",$A7))),"", $W7) | P7: =IF($A7="","",SUMIFS(Trade_Reports!$U$3:$U$502,Trade_Reports!$H$3:$H$502,$A7,Trade_Reports!$M$3:$M$502,"APPROVED",Trade_Reports!$Q$3:$Q$502,"<="&Settings!$B$4)) -> 0 | Q7: =IF($A7="","",SUMIFS(Trade_Reports!$U$3:$U$502,Trade_Reports!$H$3:$H$502,$A7,Trade_Reports!$M$3:$M$502,"APPROVED",Trade_Reports!$Q$3:$Q$502,"<="&Settings!$B$5)) -> 0 | R7: =IF($A7="","",IF($Q7=0,"",IFERROR(_xludf.MINIFS(Trade_Reports!$I$3:$I$502,Trade_Reports!$H$3:$H$502,$A7,Trade_Reports!$M$3:$M$502,"APPROVED",Trade_Reports!$Q$3:$Q$502,"<="&Settings!$B$5,Trade_Reports!$X$3:$X$502,">="&0.5*$Q7),""))) | S7: =IF($A7="","",COUNTIFS(Trade_Reports!$H$3:$H$502,$A7,Trade_Reports!$M$3:$M$502,"APPROVED",Trade_Reports!$Q$3:$Q$502,"<="&Settings!$B$5)) -> 0 | V7: =IF(OR($A7="",ISERROR(SEARCH("_",$A7))),"",IFERROR(SUMIFS(Trade_Reports!$Z$3:$Z$502,Trade_Reports!$H$3:$H$502,$A7,Trade_Reports!$M$3:$M$502,"APPROVED")/SUMIFS(Trade_Reports!$U$3:$U$502,Trade_Reports!$H$3:$H$502,$A7,Trade_Reports!$M$3:$M$502,"APPROVED"),"")) | W7: =IF($V7="","",IF($V7<1.75,"LOW",IF($V7<2.5,"MID","HIGH")))
A8: FRUIT_KAGE | F8: =IF($A8="","",IF($K8<Settings!$B$14,"",IF($P8=0,"",IFERROR(_xludf.MINIFS(Trade_Reports!$I$3:$I$502,Trade_Reports!$H$3:$H$502,$A8,Trade_Reports!$M$3:$M$502,"APPROVED",Trade_Reports!$Q$3:$Q$502,"<="&Settings!$B$4,Trade_Reports!$W$3:$W$502,">="&0.5*$P8),"")))) | G8: =IF($A8="","",IF($K8=0,"",IFERROR(_xludf.MINIFS(Trade_Reports!$I$3:$I$502,Trade_Reports!$H$3:$H$502,$A8,Trade_Reports!$M$3:$M$502,"APPROVED",Trade_Reports!$Q$3:$Q$502,"<="&Settings!$B$4),""))) | H8: =IF($A8="","",IF($K8=0,"",IFERROR(_xludf.MAXIFS(Trade_Reports!$I$3:$I$502,Trade_Reports!$H$3:$H$502,$A8,Trade_Reports!$M$3:$M$502,"APPROVED",Trade_Reports!$Q$3:$Q$502,"<="&Settings!$B$4),""))) | I8: =IF($A8="","",IF($F8="","",IF($Q8="","",IF(ABS($F8-$Q8)/$Q8<=Settings!$B$18,"STABLE",IF($F8>$Q8,"UP","DOWN"))))) | J8: =IF($A8="","",IF($K8=0,"",MIN(1,ROUND($K8/Settings!$B$14,2)))) | K8: =IF($A8="","",COUNTIFS(Trade_Reports!$H$3:$H$502,$A8,Trade_Reports!$M$3:$M$502,"APPROVED",Trade_Reports!$Q$3:$Q$502,"<="&Settings!$B$4)) -> 0 | L8: =IF($A8="","",IF($K8=0,"",IFERROR(_xludf.MAXIFS(Trade_Reports!$O$3:$O$502,Trade_Reports!$H$3:$H$502,$A8,Trade_Reports!$M$3:$M$502,"APPROVED"),""))) | M8: NO | O8: =IF(OR($A8="",ISERROR(SEARCH("_",$A8))),"", $W8) | P8: =IF($A8="","",SUMIFS(Trade_Reports!$U$3:$U$502,Trade_Reports!$H$3:$H$502,$A8,Trade_Reports!$M$3:$M$502,"APPROVED",Trade_Reports!$Q$3:$Q$502,"<="&Settings!$B$4)) -> 0 | Q8: =IF($A8="","",SUMIFS(Trade_Reports!$U$3:$U$502,Trade_Reports!$H$3:$H$502,$A8,Trade_Reports!$M$3:$M$502,"APPROVED",Trade_Reports!$Q$3:$Q$502,"<="&Settings!$B$5)) -> 0 | R8: =IF($A8="","",IF($Q8=0,"",IFERROR(_xludf.MINIFS(Trade_Reports!$I$3:$I$502,Trade_Reports!$H$3:$H$502,$A8,Trade_Reports!$M$3:$M$502,"APPROVED",Trade_Reports!$Q$3:$Q$502,"<="&Settings!$B$5,Trade_Reports!$X$3:$X$502,">="&0.5*$Q8),""))) | S8: =IF($A8="","",COUNTIFS(Trade_Reports!$H$3:$H$502,$A8,Trade_Reports!$M$3:$M$502,"APPROVED",Trade_Reports!$Q$3:$Q$502,"<="&Settings!$B$5)) -> 0 | V8: =IF(OR($A8="",ISERROR(SEARCH("_",$A8))),"",IFERROR(SUMIFS(Trade_Reports!$Z$3:$Z$502,Trade_Reports!$H$3:$H$502,$A8,Trade_Reports!$M$3:$M$502,"APPROVED")/SUMIFS(Trade_Reports!$U$3:$U$502,Trade_Reports!$H$3:$H$502,$A8,Trade_Reports!$M$3:$M$502,"APPROVED"),"")) | W8: =IF($V8="","",IF($V8<1.75,"LOW",IF($V8<2.5,"MID","HIGH")))
A9: FRUIT_GURA | F9: =IF($A9="","",IF($K9<Settings!$B$14,"",IF($P9=0,"",IFERROR(_xludf.MINIFS(Trade_Reports!$I$3:$I$502,Trade_Reports!$H$3:$H$502,$A9,Trade_Reports!$M$3:$M$502,"APPROVED",Trade_Reports!$Q$3:$Q$502,"<="&Settings!$B$4,Trade_Reports!$W$3:$W$502,">="&0.5*$P9),"")))) | G9: =IF($A9="","",IF($K9=0,"",IFERROR(_xludf.MINIFS(Trade_Reports!$I$3:$I$502,Trade_Reports!$H$3:$H$502,$A9,Trade_Reports!$M$3:$M$502,"APPROVED",Trade_Reports!$Q$3:$Q$502,"<="&Settings!$B$4),""))) | H9: =IF($A9="","",IF($K9=0,"",IFERROR(_xludf.MAXIFS(Trade_Reports!$I$3:$I$502,Trade_Reports!$H$3:$H$502,$A9,Trade_Reports!$M$3:$M$502,"APPROVED",Trade_Reports!$Q$3:$Q$502,"<="&Settings!$B$4),""))) | I9: =IF($A9="","",IF($F9="","",IF($Q9="","",IF(ABS($F9-$Q9)/$Q9<=Settings!$B$18,"STABLE",IF($F9>$Q9,"UP","DOWN"))))) | J9: =IF($A9="","",IF($K9=0,"",MIN(1,ROUND($K9/Settings!$B$14,2)))) | K9: =IF($A9="","",COUNTIFS(Trade_Reports!$H$3:$H$502,$A9,Trade_Reports!$M$3:$M$502,"APPROVED",Trade_Reports!$Q$3:$Q$502,"<="&Settings!$B$4)) -> 0 | L9: =IF($A9="","",IF($K9=0,"",IFERROR(_xludf.MAXIFS(Trade_Reports!$O$3:$O$502,Trade_Reports!$H$3:$H$502,$A9,Trade_Reports!$M$3:$M$502,"APPROVED"),""))) | M9: NO | O9: =IF(OR($A9="",ISERROR(SEARCH("_",$A9))),"", $W9) | P9: =IF($A9="","",SUMIFS(Trade_Reports!$U$3:$U$502,Trade_Reports!$H$3:$H$502,$A9,Trade_Reports!$M$3:$M$502,"APPROVED",Trade_Reports!$Q$3:$Q$502,"<="&Settings!$B$4)) -> 0 | Q9: =IF($A9="","",SUMIFS(Trade_Reports!$U$3:$U$502,Trade_Reports!$H$3:$H$502,$A9,Trade_Reports!$M$3:$M$502,"APPROVED",Trade_Reports!$Q$3:$Q$502,"<="&Settings!$B$5)) -> 0 | R9: =IF($A9="","",IF($Q9=0,"",IFERROR(_xludf.MINIFS(Trade_Reports!$I$3:$I$502,Trade_Reports!$H$3:$H$502,$A9,Trade_Reports!$M$3:$M$502,"APPROVED",Trade_Reports!$Q$3:$Q$502,"<="&Settings!$B$5,Trade_Reports!$X$3:$X$502,">="&0.5*$Q9),""))) | S9: =IF($A9="","",COUNTIFS(Trade_Reports!$H$3:$H$502,$A9,Trade_Reports!$M$3:$M$502,"APPROVED",Trade_Reports!$Q$3:$Q$502,"<="&Settings!$B$5)) -> 0 | V9: =IF(OR($A9="",ISERROR(SEARCH("_",$A9))),"",IFERROR(SUMIFS(Trade_Reports!$Z$3:$Z$502,Trade_Reports!$H$3:$H$502,$A9,Trade_Reports!$M$3:$M$502,"APPROVED")/SUMIFS(Trade_Reports!$U$3:$U$502,Trade_Reports!$H$3:$H$502,$A9,Trade_Reports!$M$3:$M$502,"APPROVED"),"")) | W9: =IF($V9="","",IF($V9<1.75,"LOW",IF($V9<2.5,"MID","HIGH")))
A10: FRUIT_GORO | F10: =IF($A10="","",IF($K10<Settings!$B$14,"",IF($P10=0,"",IFERROR(_xludf.MINIFS(Trade_Reports!$I$3:$I$502,Trade_Reports!$H$3:$H$502,$A10,Trade_Reports!$M$3:$M$502,"APPROVED",Trade_Reports!$Q$3:$Q$502,"<="&Settings!$B$4,Trade_Reports!$W$3:$W$502,">="&0.5*$P10),"")))) | G10: =IF($A10="","",IF($K10=0,"",IFERROR(_xludf.MINIFS(Trade_Reports!$I$3:$I$502,Trade_Reports!$H$3:$H$502,$A10,Trade_Reports!$M$3:$M$502,"APPROVED",Trade_Reports!$Q$3:$Q$502,"<="&Settings!$B$4),""))) | H10: =IF($A10="","",IF($K10=0,"",IFERROR(_xludf.MAXIFS(Trade_Reports!$I$3:$I$502,Trade_Reports!$H$3:$H$502,$A10,Trade_Reports!$M$3:$M$502,"APPROVED",Trade_Reports!$Q$3:$Q$502,"<="&Settings!$B$4),""))) | I10: =IF($A10="","",IF($F10="","",IF($Q10="","",IF(ABS($F10-$Q10)/$Q10<=Settings!$B$18,"STABLE",IF($F10>$Q10,"UP","DOWN"))))) | J10: =IF($A10="","",IF($K10=0,"",MIN(1,ROUND($K10/Settings!$B$14,2)))) | K10: =IF($A10="","",COUNTIFS(Trade_Reports!$H$3:$H$502,$A10,Trade_Reports!$M$3:$M$502,"APPROVED",Trade_Reports!$Q$3:$Q$502,"<="&Settings!$B$4)) -> 0 | L10: =IF($A10="","",IF($K10=0,"",IFERROR(_xludf.MAXIFS(Trade_Reports!$O$3:$O$502,Trade_Reports!$H$3:$H$502,$A10,Trade_Reports!$M$3:$M$502,"APPROVED"),""))) | M10: NO | O10: =IF(OR($A10="",ISERROR(SEARCH("_",$A10))),"", $W10) | P10: =IF($A10="","",SUMIFS(Trade_Reports!$U$3:$U$502,Trade_Reports!$H$3:$H$502,$A10,Trade_Reports!$M$3:$M$502,"APPROVED",Trade_Reports!$Q$3:$Q$502,"<="&Settings!$B$4)) -> 0 | Q10: =IF($A10="","",SUMIFS(Trade_Reports!$U$3:$U$502,Trade_Reports!$H$3:$H$502,$A10,Trade_Reports!$M$3:$M$502,"APPROVED",Trade_Reports!$Q$3:$Q$502,"<="&Settings!$B$5)) -> 0 | R10: =IF($A10="","",IF($Q10=0,"",IFERROR(_xludf.MINIFS(Trade_Reports!$I$3:$I$502,Trade_Reports!$H$3:$H$502,$A10,Trade_Reports!$M$3:$M$502,"APPROVED",Trade_Reports!$Q$3:$Q$502,"<="&Settings!$B$5,Trade_Reports!$X$3:$X$502,">="&0.5*$Q10),""))) | S10: =IF($A10="","",COUNTIFS(Trade_Reports!$H$3:$H$502,$A10,Trade_Reports!$M$3:$M$502,"APPROVED",Trade_Reports!$Q$3:$Q$502,"<="&Settings!$B$5)) -> 0 | V10: =IF(OR($A10="",ISERROR(SEARCH("_",$A10))),"",IFERROR(SUMIFS(Trade_Reports!$Z$3:$Z$502,Trade_Reports!$H$3:$H$502,$A10,Trade_Reports!$M$3:$M$502,"APPROVED")/SUMIFS(Trade_Reports!$U$3:$U$502,Trade_Reports!$H$3:$H$502,$A10,Trade_Reports!$M$3:$M$502,"APPROVED"),"")) | W10: =IF($V10="","",IF($V10<1.75,"LOW",IF($V10<2.5,"MID","HIGH")))
A11: FRUIT_YAMI | F11: =IF($A11="","",IF($K11<Settings!$B$14,"",IF($P11=0,"",IFERROR(_xludf.MINIFS(Trade_Reports!$I$3:$I$502,Trade_Reports!$H$3:$H$502,$A11,Trade_Reports!$M$3:$M$502,"APPROVED",Trade_Reports!$Q$3:$Q$502,"<="&Settings!$B$4,Trade_Reports!$W$3:$W$502,">="&0.5*$P11),"")))) | G11: =IF($A11="","",IF($K11=0,"",IFERROR(_xludf.MINIFS(Trade_Reports!$I$3:$I$502,Trade_Reports!$H$3:$H$502,$A11,Trade_Reports!$M$3:$M$502,"APPROVED",Trade_Reports!$Q$3:$Q$502,"<="&Settings!$B$4),""))) | H11: =IF($A11="","",IF($K11=0,"",IFERROR(_xludf.MAXIFS(Trade_Reports!$I$3:$I$502,Trade_Reports!$H$3:$H$502,$A11,Trade_Reports!$M$3:$M$502,"APPROVED",Trade_Reports!$Q$3:$Q$502,"<="&Settings!$B$4),""))) | I11: =IF($A11="","",IF($F11="","",IF($Q11="","",IF(ABS($F11-$Q11)/$Q11<=Settings!$B$18,"STABLE",IF($F11>$Q11,"UP","DOWN"))))) | J11: =IF($A11="","",IF($K11=0,"",MIN(1,ROUND($K11/Settings!$B$14,2)))) | K11: =IF($A11="","",COUNTIFS(Trade_Reports!$H$3:$H$502,$A11,Trade_Reports!$M$3:$M$502,"APPROVED",Trade_Reports!$Q$3:$Q$502,"<="&Settings!$B$4)) -> 0 | L11: =IF($A11="","",IF($K11=0,"",IFERROR(_xludf.MAXIFS(Trade_Reports!$O$3:$O$502,Trade_Reports!$H$3:$H$502,$A11,Trade_Reports!$M$3:$M$502,"APPROVED"),""))) | M11: NO | O11: =IF(OR($A11="",ISERROR(SEARCH("_",$A11))),"", $W11) | P11: =IF($A11="","",SUMIFS(Trade_Reports!$U$3:$U$502,Trade_Reports!$H$3:$H$502,$A11,Trade_Reports!$M$3:$M$502,"APPROVED",Trade_Reports!$Q$3:$Q$502,"<="&Settings!$B$4)) -> 0 | Q11: =IF($A11="","",SUMIFS(Trade_Reports!$U$3:$U$502,Trade_Reports!$H$3:$H$502,$A11,Trade_Reports!$M$3:$M$502,"APPROVED",Trade_Reports!$Q$3:$Q$502,"<="&Settings!$B$5)) -> 0 | R11: =IF($A11="","",IF($Q11=0,"",IFERROR(_xludf.MINIFS(Trade_Reports!$I$3:$I$502,Trade_Reports!$H$3:$H$502,$A11,Trade_Reports!$M$3:$M$502,"APPROVED",Trade_Reports!$Q$3:$Q$502,"<="&Settings!$B$5,Trade_Reports!$X$3:$X$502,">="&0.5*$Q11),""))) | S11: =IF($A11="","",COUNTIFS(Trade_Reports!$H$3:$H$502,$A11,Trade_Reports!$M$3:$M$502,"APPROVED",Trade_Reports!$Q$3:$Q$502,"<="&Settings!$B$5)) -> 0 | V11: =IF(OR($A11="",ISERROR(SEARCH("_",$A11))),"",IFERROR(SUMIFS(Trade_Reports!$Z$3:$Z$502,Trade_Reports!$H$3:$H$502,$A11,Trade_Reports!$M$3:$M$502,"APPROVED")/SUMIFS(Trade_Reports!$U$3:$U$502,Trade_Reports!$H$3:$H$502,$A11,Trade_Reports!$M$3:$M$502,"APPROVED"),"")) | W11: =IF($V11="","",IF($V11<1.75,"LOW",IF($V11<2.5,"MID","HIGH")))
A12: FRUIT_ZUZHI | F12: =IF($A12="","",IF($K12<Settings!$B$14,"",IF($P12=0,"",IFERROR(_xludf.MINIFS(Trade_Reports!$I$3:$I$502,Trade_Reports!$H$3:$H$502,$A12,Trade_Reports!$M$3:$M$502,"APPROVED",Trade_Reports!$Q$3:$Q$502,"<="&Settings!$B$4,Trade_Reports!$W$3:$W$502,">="&0.5*$P12),"")))) | G12: =IF($A12="","",IF($K12=0,"",IFERROR(_xludf.MINIFS(Trade_Reports!$I$3:$I$502,Trade_Reports!$H$3:$H$502,$A12,Trade_Reports!$M$3:$M$502,"APPROVED",Trade_Reports!$Q$3:$Q$502,"<="&Settings!$B$4),""))) | H12: =IF($A12="","",IF($K12=0,"",IFERROR(_xludf.MAXIFS(Trade_Reports!$I$3:$I$502,Trade_Reports!$H$3:$H$502,$A12,Trade_Reports!$M$3:$M$502,"APPROVED",Trade_Reports!$Q$3:$Q$502,"<="&Settings!$B$4),""))) | I12: =IF($A12="","",IF($F12="","",IF($Q12="","",IF(ABS($F12-$Q12)/$Q12<=Settings!$B$18,"STABLE",IF($F12>$Q12,"UP","DOWN"))))) | J12: =IF($A12="","",IF($K12=0,"",MIN(1,ROUND($K12/Settings!$B$14,2)))) | K12: =IF($A12="","",COUNTIFS(Trade_Reports!$H$3:$H$502,$A12,Trade_Reports!$M$3:$M$502,"APPROVED",Trade_Reports!$Q$3:$Q$502,"<="&Settings!$B$4)) -> 0 | L12: =IF($A12="","",IF($K12=0,"",IFERROR(_xludf.MAXIFS(Trade_Reports!$O$3:$O$502,Trade_Reports!$H$3:$H$502,$A12,Trade_Reports!$M$3:$M$502,"APPROVED"),""))) | M12: NO | O12: =IF(OR($A12="",ISERROR(SEARCH("_",$A12))),"", $W12) | P12: =IF($A12="","",SUMIFS(Trade_Reports!$U$3:$U$502,Trade_Reports!$H$3:$H$502,$A12,Trade_Reports!$M$3:$M$502,"APPROVED",Trade_Reports!$Q$3:$Q$502,"<="&Settings!$B$4)) -> 0 | Q12: =IF($A12="","",SUMIFS(Trade_Reports!$U$3:$U$502,Trade_Reports!$H$3:$H$502,$A12,Trade_Reports!$M$3:$M$502,"APPROVED",Trade_Reports!$Q$3:$Q$502,"<="&Settings!$B$5)) -> 0 | R12: =IF($A12="","",IF($Q12=0,"",IFERROR(_xludf.MINIFS(Trade_Reports!$I$3:$I$502,Trade_Reports!$H$3:$H$502,$A12,Trade_Reports!$M$3:$M$502,"APPROVED",Trade_Reports!$Q$3:$Q$502,"<="&Settings!$B$5,Trade_Reports!$X$3:$X$502,">="&0.5*$Q12),""))) | S12: =IF($A12="","",COUNTIFS(Trade_Reports!$H$3:$H$502,$A12,Trade_Reports!$M$3:$M$502,"APPROVED",Trade_Reports!$Q$3:$Q$502,"<="&Settings!$B$5)) -> 0 | V12: =IF(OR($A12="",ISERROR(SEARCH("_",$A12))),"",IFERROR(SUMIFS(Trade_Reports!$Z$3:$Z$502,Trade_Reports!$H$3:$H$502,$A12,Trade_Reports!$M$3:$M$502,"APPROVED")/SUMIFS(Trade_Reports!$U$3:$U$502,Trade_Reports!$H$3:$H$502,$A12,Trade_Reports!$M$3:$M$502,"APPROVED"),"")) | W12: =IF($V12="","",IF($V12<1.75,"LOW",IF($V12<2.5,"MID","HIGH")))
A13: FRUIT_HIE | F13: =IF($A13="","",IF($K13<Settings!$B$14,"",IF($P13=0,"",IFERROR(_xludf.MINIFS(Trade_Reports!$I$3:$I$502,Trade_Reports!$H$3:$H$502,$A13,Trade_Reports!$M$3:$M$502,"APPROVED",Trade_Reports!$Q$3:$Q$502,"<="&Settings!$B$4,Trade_Reports!$W$3:$W$502,">="&0.5*$P13),"")))) | G13: =IF($A13="","",IF($K13=0,"",IFERROR(_xludf.MINIFS(Trade_Reports!$I$3:$I$502,Trade_Reports!$H$3:$H$502,$A13,Trade_Reports!$M$3:$M$502,"APPROVED",Trade_Reports!$Q$3:$Q$502,"<="&Settings!$B$4),""))) | H13: =IF($A13="","",IF($K13=0,"",IFERROR(_xludf.MAXIFS(Trade_Reports!$I$3:$I$502,Trade_Reports!$H$3:$H$502,$A13,Trade_Reports!$M$3:$M$502,"APPROVED",Trade_Reports!$Q$3:$Q$502,"<="&Settings!$B$4),""))) | I13: =IF($A13="","",IF($F13="","",IF($Q13="","",IF(ABS($F13-$Q13)/$Q13<=Settings!$B$18,"STABLE",IF($F13>$Q13,"UP","DOWN"))))) | J13: =IF($A13="","",IF($K13=0,"",MIN(1,ROUND($K13/Settings!$B$14,2)))) | K13: =IF($A13="","",COUNTIFS(Trade_Reports!$H$3:$H$502,$A13,Trade_Reports!$M$3:$M$502,"APPROVED",Trade_Reports!$Q$3:$Q$502,"<="&Settings!$B$4)) -> 0 | L13: =IF($A13="","",IF($K13=0,"",IFERROR(_xludf.MAXIFS(Trade_Reports!$O$3:$O$502,Trade_Reports!$H$3:$H$502,$A13,Trade_Reports!$M$3:$M$502,"APPROVED"),""))) | M13: NO | O13: =IF(OR($A13="",ISERROR(SEARCH("_",$A13))),"", $W13) | P13: =IF($A13="","",SUMIFS(Trade_Reports!$U$3:$U$502,Trade_Reports!$H$3:$H$502,$A13,Trade_Reports!$M$3:$M$502,"APPROVED",Trade_Reports!$Q$3:$Q$502,"<="&Settings!$B$4)) -> 0 | Q13: =IF($A13="","",SUMIFS(Trade_Reports!$U$3:$U$502,Trade_Reports!$H$3:$H$502,$A13,Trade_Reports!$M$3:$M$502,"APPROVED",Trade_Reports!$Q$3:$Q$502,"<="&Settings!$B$5)) -> 0 | R13: =IF($A13="","",IF($Q13=0,"",IFERROR(_xludf.MINIFS(Trade_Reports!$I$3:$I$502,Trade_Reports!$H$3:$H$502,$A13,Trade_Reports!$M$3:$M$502,"APPROVED",Trade_Reports!$Q$3:$Q$502,"<="&Settings!$B$5,Trade_Reports!$X$3:$X$502,">="&0.5*$Q13),""))) | S13: =IF($A13="","",COUNTIFS(Trade_Reports!$H$3:$H$502,$A13,Trade_Reports!$M$3:$M$502,"APPROVED",Trade_Reports!$Q$3:$Q$502,"<="&Settings!$B$5)) -> 0 | V13: =IF(OR($A13="",ISERROR(SEARCH("_",$A13))),"",IFERROR(SUMIFS(Trade_Reports!$Z$3:$Z$502,Trade_Reports!$H$3:$H$502,$A13,Trade_Reports!$M$3:$M$502,"APPROVED")/SUMIFS(Trade_Reports!$U$3:$U$502,Trade_Reports!$H$3:$H$502,$A13,Trade_Reports!$M$3:$M$502,"APPROVED"),"")) | W13: =IF($V13="","",IF($V13<1.75,"LOW",IF($V13<2.5,"MID","HIGH")))
A14: FRUIT_SUNA | F14: =IF($A14="","",IF($K14<Settings!$B$14,"",IF($P14=0,"",IFERROR(_xludf.MINIFS(Trade_Reports!$I$3:$I$502,Trade_Reports!$H$3:$H$502,$A14,Trade_Reports!$M$3:$M$502,"APPROVED",Trade_Reports!$Q$3:$Q$502,"<="&Settings!$B$4,Trade_Reports!$W$3:$W$502,">="&0.5*$P14),"")))) | G14: =IF($A14="","",IF($K14=0,"",IFERROR(_xludf.MINIFS(Trade_Reports!$I$3:$I$502,Trade_Reports!$H$3:$H$502,$A14,Trade_Reports!$M$3:$M$502,"APPROVED",Trade_Reports!$Q$3:$Q$502,"<="&Settings!$B$4),""))) | H14: =IF($A14="","",IF($K14=0,"",IFERROR(_xludf.MAXIFS(Trade_Reports!$I$3:$I$502,Trade_Reports!$H$3:$H$502,$A14,Trade_Reports!$M$3:$M$502,"APPROVED",Trade_Reports!$Q$3:$Q$502,"<="&Settings!$B$4),""))) | I14: =IF($A14="","",IF($F14="","",IF($Q14="","",IF(ABS($F14-$Q14)/$Q14<=Settings!$B$18,"STABLE",IF($F14>$Q14,"UP","DOWN"))))) | J14: =IF($A14="","",IF($K14=0,"",MIN(1,ROUND($K14/Settings!$B$14,2)))) | K14: =IF($A14="","",COUNTIFS(Trade_Reports!$H$3:$H$502,$A14,Trade_Reports!$M$3:$M$502,"APPROVED",Trade_Reports!$Q$3:$Q$502,"<="&Settings!$B$4)) -> 0 | L14: =IF($A14="","",IF($K14=0,"",IFERROR(_xludf.MAXIFS(Trade_Reports!$O$3:$O$502,Trade_Reports!$H$3:$H$502,$A14,Trade_Reports!$M$3:$M$502,"APPROVED"),""))) | M14: NO | O14: =IF(OR($A14="",ISERROR(SEARCH("_",$A14))),"", $W14) | P14: =IF($A14="","",SUMIFS(Trade_Reports!$U$3:$U$502,Trade_Reports!$H$3:$H$502,$A14,Trade_Reports!$M$3:$M$502,"APPROVED",Trade_Reports!$Q$3:$Q$502,"<="&Settings!$B$4)) -> 0 | Q14: =IF($A14="","",SUMIFS(Trade_Reports!$U$3:$U$502,Trade_Reports!$H$3:$H$502,$A14,Trade_Reports!$M$3:$M$502,"APPROVED",Trade_Reports!$Q$3:$Q$502,"<="&Settings!$B$5)) -> 0 | R14: =IF($A14="","",IF($Q14=0,"",IFERROR(_xludf.MINIFS(Trade_Reports!$I$3:$I$502,Trade_Reports!$H$3:$H$502,$A14,Trade_Reports!$M$3:$M$502,"APPROVED",Trade_Reports!$Q$3:$Q$502,"<="&Settings!$B$5,Trade_Reports!$X$3:$X$502,">="&0.5*$Q14),""))) | S14: =IF($A14="","",COUNTIFS(Trade_Reports!$H$3:$H$502,$A14,Trade_Reports!$M$3:$M$502,"APPROVED",Trade_Reports!$Q$3:$Q$502,"<="&Settings!$B$5)) -> 0 | V14: =IF(OR($A14="",ISERROR(SEARCH("_",$A14))),"",IFERROR(SUMIFS(Trade_Reports!$Z$3:$Z$502,Trade_Reports!$H$3:$H$502,$A14,Trade_Reports!$M$3:$M$502,"APPROVED")/SUMIFS(Trade_Reports!$U$3:$U$502,Trade_Reports!$H$3:$H$502,$A14,Trade_Reports!$M$3:$M$502,"APPROVED"),"")) | W14: =IF($V14="","",IF($V14<1.75,"LOW",IF($V14<2.5,"MID","HIGH")))
A15: FRUIT_YUKI | F15: =IF($A15="","",IF($K15<Settings!$B$14,"",IF($P15=0,"",IFERROR(_xludf.MINIFS(Trade_Reports!$I$3:$I$502,Trade_Reports!$H$3:$H$502,$A15,Trade_Reports!$M$3:$M$502,"APPROVED",Trade_Reports!$Q$3:$Q$502,"<="&Settings!$B$4,Trade_Reports!$W$3:$W$502,">="&0.5*$P15),"")))) | G15: =IF($A15="","",IF($K15=0,"",IFERROR(_xludf.MINIFS(Trade_Reports!$I$3:$I$502,Trade_Reports!$H$3:$H$502,$A15,Trade_Reports!$M$3:$M$502,"APPROVED",Trade_Reports!$Q$3:$Q$502,"<="&Settings!$B$4),""))) | H15: =IF($A15="","",IF($K15=0,"",IFERROR(_xludf.MAXIFS(Trade_Reports!$I$3:$I$502,Trade_Reports!$H$3:$H$502,$A15,Trade_Reports!$M$3:$M$502,"APPROVED",Trade_Reports!$Q$3:$Q$502,"<="&Settings!$B$4),""))) | I15: =IF($A15="","",IF($F15="","",IF($Q15="","",IF(ABS($F15-$Q15)/$Q15<=Settings!$B$18,"STABLE",IF($F15>$Q15,"UP","DOWN"))))) | J15: =IF($A15="","",IF($K15=0,"",MIN(1,ROUND($K15/Settings!$B$14,2)))) | K15: =IF($A15="","",COUNTIFS(Trade_Reports!$H$3:$H$502,$A15,Trade_Reports!$M$3:$M$502,"APPROVED",Trade_Reports!$Q$3:$Q$502,"<="&Settings!$B$4)) -> 0 | L15: =IF($A15="","",IF($K15=0,"",IFERROR(_xludf.MAXIFS(Trade_Reports!$O$3:$O$502,Trade_Reports!$H$3:$H$502,$A15,Trade_Reports!$M$3:$M$502,"APPROVED"),""))) | M15: NO | O15: =IF(OR($A15="",ISERROR(SEARCH("_",$A15))),"", $W15) | P15: =IF($A15="","",SUMIFS(Trade_Reports!$U$3:$U$502,Trade_Reports!$H$3:$H$502,$A15,Trade_Reports!$M$3:$M$502,"APPROVED",Trade_Reports!$Q$3:$Q$502,"<="&Settings!$B$4)) -> 0 | Q15: =IF($A15="","",SUMIFS(Trade_Reports!$U$3:$U$502,Trade_Reports!$H$3:$H$502,$A15,Trade_Reports!$M$3:$M$502,"APPROVED",Trade_Reports!$Q$3:$Q$502,"<="&Settings!$B$5)) -> 0 | R15: =IF($A15="","",IF($Q15=0,"",IFERROR(_xludf.MINIFS(Trade_Reports!$I$3:$I$502,Trade_Reports!$H$3:$H$502,$A15,Trade_Reports!$M$3:$M$502,"APPROVED",Trade_Reports!$Q$3:$Q$502,"<="&Settings!$B$5,Trade_Reports!$X$3:$X$502,">="&0.5*$Q15),""))) | S15: =IF($A15="","",COUNTIFS(Trade_Reports!$H$3:$H$502,$A15,Trade_Reports!$M$3:$M$502,"APPROVED",Trade_Reports!$Q$3:$Q$502,"<="&Settings!$B$5)) -> 0 | V15: =IF(OR($A15="",ISERROR(SEARCH("_",$A15))),"",IFERROR(SUMIFS(Trade_Reports!$Z$3:$Z$502,Trade_Reports!$H$3:$H$502,$A15,Trade_Reports!$M$3:$M$502,"APPROVED")/SUMIFS(Trade_Reports!$U$3:$U$502,Trade_Reports!$H$3:$H$502,$A15,Trade_Reports!$M$3:$M$502,"APPROVED"),"")) | W15: =IF($V15="","",IF($V15<1.75,"LOW",IF($V15<2.5,"MID","HIGH")))
A16: FRUIT_MERA | F16: =IF($A16="","",IF($K16<Settings!$B$14,"",IF($P16=0,"",IFERROR(_xludf.MINIFS(Trade_Reports!$I$3:$I$502,Trade_Reports!$H$3:$H$502,$A16,Trade_Reports!$M$3:$M$502,"APPROVED",Trade_Reports!$Q$3:$Q$502,"<="&Settings!$B$4,Trade_Reports!$W$3:$W$502,">="&0.5*$P16),"")))) | G16: =IF($A16="","",IF($K16=0,"",IFERROR(_xludf.MINIFS(Trade_Reports!$I$3:$I$502,Trade_Reports!$H$3:$H$502,$A16,Trade_Reports!$M$3:$M$502,"APPROVED",Trade_Reports!$Q$3:$Q$502,"<="&Settings!$B$4),""))) | H16: =IF($A16="","",IF($K16=0,"",IFERROR(_xludf.MAXIFS(Trade_Reports!$I$3:$I$502,Trade_Reports!$H$3:$H$502,$A16,Trade_Reports!$M$3:$M$502,"APPROVED",Trade_Reports!$Q$3:$Q$502,"<="&Settings!$B$4),""))) | I16: =IF($A16="","",IF($F16="","",IF($Q16="","",IF(ABS($F16-$Q16)/$Q16<=Settings!$B$18,"STABLE",IF($F16>$Q16,"UP","DOWN"))))) | J16: =IF($A16="","",IF($K16=0,"",MIN(1,ROUND($K16/Settings!$B$14,2)))) | K16: =IF($A16="","",COUNTIFS(Trade_Reports!$H$3:$H$502,$A16,Trade_Reports!$M$3:$M$502,"APPROVED",Trade_Reports!$Q$3:$Q$502,"<="&Settings!$B$4)) -> 0 | L16: =IF($A16="","",IF($K16=0,"",IFERROR(_xludf.MAXIFS(Trade_Reports!$O$3:$O$502,Trade_Reports!$H$3:$H$502,$A16,Trade_Reports!$M$3:$M$502,"APPROVED"),""))) | M16: NO | O16: =IF(OR($A16="",ISERROR(SEARCH("_",$A16))),"", $W16) | P16: =IF($A16="","",SUMIFS(Trade_Reports!$U$3:$U$502,Trade_Reports!$H$3:$H$502,$A16,Trade_Reports!$M$3:$M$502,"APPROVED",Trade_Reports!$Q$3:$Q$502,"<="&Settings!$B$4)) -> 0 | Q16: =IF($A16="","",SUMIFS(Trade_Reports!$U$3:$U$502,Trade_Reports!$H$3:$H$502,$A16,Trade_Reports!$M$3:$M$502,"APPROVED",Trade_Reports!$Q$3:$Q$502,"<="&Settings!$B$5)) -> 0 | R16: =IF($A16="","",IF($Q16=0,"",IFERROR(_xludf.MINIFS(Trade_Reports!$I$3:$I$502,Trade_Reports!$H$3:$H$502,$A16,Trade_Reports!$M$3:$M$502,"APPROVED",Trade_Reports!$Q$3:$Q$502,"<="&Settings!$B$5,Trade_Reports!$X$3:$X$502,">="&0.5*$Q16),""))) | S16: =IF($A16="","",COUNTIFS(Trade_Reports!$H$3:$H$502,$A16,Trade_Reports!$M$3:$M$502,"APPROVED",Trade_Reports!$Q$3:$Q$502,"<="&Settings!$B$5)) -> 0 | V16: =IF(OR($A16="",ISERROR(SEARCH("_",$A16))),"",IFERROR(SUMIFS(Trade_Reports!$Z$3:$Z$502,Trade_Reports!$H$3:$H$502,$A16,Trade_Reports!$M$3:$M$502,"APPROVED")/SUMIFS(Trade_Reports!$U$3:$U$502,Trade_Reports!$H$3:$H$502,$A16,Trade_Reports!$M$3:$M$502,"APPROVED"),"")) | W16: =IF($V16="","",IF($V16<1.75,"LOW",IF($V16<2.5,"MID","HIGH")))
... A28: FRUIT_DRAGON | F28: =IF($A28="","",IF($K28<Settings!$B$14,"",IF($P28=0,"",IFERROR(_xludf.MINIFS(Trade_Reports!$I$3:$I$502,Trade_Reports!$H$3:$H$502,$A28,Trade_Reports!$M$3:$M$502,"APPROVED",Trade_Reports!$Q$3:$Q$502,"<="&Settings!$B$4,Trade_Reports!$W$3:$W$502,">="&0.5*$P28),"")))) | G28: =IF($A28="","",IF($K28=0,"",IFERROR(_xludf.MINIFS(Trade_Reports!$I$3:$I$502,Trade_Reports!$H$3:$H$502,$A28,Trade_Reports!$M$3:$M$502,"APPROVED",Trade_Reports!$Q$3:$Q$502,"<="&Settings!$B$4),""))) | H28: =IF($A28="","",IF($K28=0,"",IFERROR(_xludf.MAXIFS(Trade_Reports!$I$3:$I$502,Trade_Reports!$H$3:$H$502,$A28,Trade_Reports!$M$3:$M$502,"APPROVED",Trade_Reports!$Q$3:$Q$502,"<="&Settings!$B$4),""))) | I28: =IF($A28="","",IF($F28="","",IF($Q28="","",IF(ABS($F28-$Q28)/$Q28<=Settings!$B$18,"STABLE",IF($F28>$Q28,"UP","DOWN"))))) | J28: =IF($A28="","",IF($K28=0,"",MIN(1,ROUND($K28/Settings!$B$14,2)))) | K28: =IF($A28="","",COUNTIFS(Trade_Reports!$H$3:$H$502,$A28,Trade_Reports!$M$3:$M$502,"APPROVED",Trade_Reports!$Q$3:$Q$502,"<="&Settings!$B$4)) -> 0 | L28: =IF($A28="","",IF($K28=0,"",IFERROR(_xludf.MAXIFS(Trade_Reports!$O$3:$O$502,Trade_Reports!$H$3:$H$502,$A28,Trade_Reports!$M$3:$M$502,"APPROVED"),""))) | M28: NO | O28: =IF(OR($A28="",ISERROR(SEARCH("_",$A28))),"", $W28) | P28: =IF($A28="","",SUMIFS(Trade_Reports!$U$3:$U$502,Trade_Reports!$H$3:$H$502,$A28,Trade_Reports!$M$3:$M$502,"APPROVED",Trade_Reports!$Q$3:$Q$502,"<="&Settings!$B$4)) -> 0 | Q28: =IF($A28="","",SUMIFS(Trade_Reports!$U$3:$U$502,Trade_Reports!$H$3:$H$502,$A28,Trade_Reports!$M$3:$M$502,"APPROVED",Trade_Reports!$Q$3:$Q$502,"<="&Settings!$B$5)) -> 0 | R28: =IF($A28="","",IF($Q28=0,"",IFERROR(_xludf.MINIFS(Trade_Reports!$I$3:$I$502,Trade_Reports!$H$3:$H$502,$A28,Trade_Reports!$M$3:$M$502,"APPROVED",Trade_Reports!$Q$3:$Q$502,"<="&Settings!$B$5,Trade_Reports!$X$3:$X$502,">="&0.5*$Q28),""))) | S28: =IF($A28="","",COUNTIFS(Trade_Reports!$H$3:$H$502,$A28,Trade_Reports!$M$3:$M$502,"APPROVED",Trade_Reports!$Q$3:$Q$502,"<="&Settings!$B$5)) -> 0 | V28: =IF(OR($A28="",ISERROR(SEARCH("_",$A28))),"",IFERROR(SUMIFS(Trade_Reports!$Z$3:$Z$502,Trade_Reports!$H$3:$H$502,$A28,Trade_Reports!$M$3:$M$502,"APPROVED")/SUMIFS(Trade_Reports!$U$3:$U$502,Trade_Reports!$H$3:$H$502,$A28,Trade_Reports!$M$3:$M$502,"APPROVED"),"")) | W28: =IF($V28="","",IF($V28<1.75,"LOW",IF($V28<2.5,"MID","HIGH")))
F29: =IF($A29="","",IF($K29<Settings!$B$14,"",IF($P29=0,"",IFERROR(_xludf.MINIFS(Trade_Reports!$I$3:$I$502,Trade_Reports!$H$3:$H$502,$A29,Trade_Reports!$M$3:$M$502,"APPROVED",Trade_Reports!$Q$3:$Q$502,"<="&Settings!$B$4,Trade_Reports!$W$3:$W$502,">="&0.5*$P29),"")))) | G29: =IF($A29="","",IF($K29=0,"",IFERROR(_xludf.MINIFS(Trade_Reports!$I$3:$I$502,Trade_Reports!$H$3:$H$502,$A29,Trade_Reports!$M$3:$M$502,"APPROVED",Trade_Reports!$Q$3:$Q$502,"<="&Settings!$B$4),""))) | H29: =IF($A29="","",IF($K29=0,"",IFERROR(_xludf.MAXIFS(Trade_Reports!$I$3:$I$502,Trade_Reports!$H$3:$H$502,$A29,Trade_Reports!$M$3:$M$502,"APPROVED",Trade_Reports!$Q$3:$Q$502,"<="&Settings!$B$4),""))) | I29: =IF($A29="","",IF($F29="","",IF($Q29="","",IF(ABS($F29-$Q29)/$Q29<=Settings!$B$18,"STABLE",IF($F29>$Q29,"UP","DOWN"))))) | J29: =IF($A29="","",IF($K29=0,"",MIN(1,ROUND($K29/Settings!$B$14,2)))) | K29: =IF($A29="","",COUNTIFS(Trade_Reports!$H$3:$H$502,$A29,Trade_Reports!$M$3:$M$502,"APPROVED",Trade_Reports!$Q$3:$Q$502,"<="&Settings!$B$4)) | L29: =IF($A29="","",IF($K29=0,"",IFERROR(_xludf.MAXIFS(Trade_Reports!$O$3:$O$502,Trade_Reports!$H$3:$H$502,$A29,Trade_Reports!$M$3:$M$502,"APPROVED"),""))) | M29: NO | O29: =IF(OR($A29="",ISERROR(SEARCH("_",$A29))),"", $W29) | P29: =IF($A29="","",SUMIFS(Trade_Reports!$U$3:$U$502,Trade_Reports!$H$3:$H$502,$A29,Trade_Reports!$M$3:$M$502,"APPROVED",Trade_Reports!$Q$3:$Q$502,"<="&Settings!$B$4)) | Q29: =IF($A29="","",SUMIFS(Trade_Reports!$U$3:$U$502,Trade_Reports!$H$3:$H$502,$A29,Trade_Reports!$M$3:$M$502,"APPROVED",Trade_Reports!$Q$3:$Q$502,"<="&Settings!$B$5)) | R29: =IF($A29="","",IF($Q29=0,"",IFERROR(_xludf.MINIFS(Trade_Reports!$I$3:$I$502,Trade_Reports!$H$3:$H$502,$A29,Trade_Reports!$M$3:$M$502,"APPROVED",Trade_Reports!$Q$3:$Q$502,"<="&Settings!$B$5,Trade_Reports!$X$3:$X$502,">="&0.5*$Q29),""))) | S29: =IF($A29="","",COUNTIFS(Trade_Reports!$H$3:$H$502,$A29,Trade_Reports!$M$3:$M$502,"APPROVED",Trade_Reports!$Q$3:$Q$502,"<="&Settings!$B$5)) | V29: =IF(OR($A29="",ISERROR(SEARCH("_",$A29))),"",IFERROR(SUMIFS(Trade_Reports!$Z$3:$Z$502,Trade_Reports!$H$3:$H$502,$A29,Trade_Reports!$M$3:$M$502,"APPROVED")/SUMIFS(Trade_Reports!$U$3:$U$502,Trade_Reports!$H$3:$H$502,$A29,Trade_Reports!$M$3:$M$502,"APPROVED"),"")) | W29: =IF($V29="","",IF($V29<1.75,"LOW",IF($V29<2.5,"MID","HIGH")))
F30: =IF($A30="","",IF($K30<Settings!$B$14,"",IF($P30=0,"",IFERROR(_xludf.MINIFS(Trade_Reports!$I$3:$I$502,Trade_Reports!$H$3:$H$502,$A30,Trade_Reports!$M$3:$M$502,"APPROVED",Trade_Reports!$Q$3:$Q$502,"<="&Settings!$B$4,Trade_Reports!$W$3:$W$502,">="&0.5*$P30),"")))) | G30: =IF($A30="","",IF($K30=0,"",IFERROR(_xludf.MINIFS(Trade_Reports!$I$3:$I$502,Trade_Reports!$H$3:$H$502,$A30,Trade_Reports!$M$3:$M$502,"APPROVED",Trade_Reports!$Q$3:$Q$502,"<="&Settings!$B$4),""))) | H30: =IF($A30="","",IF($K30=0,"",IFERROR(_xludf.MAXIFS(Trade_Reports!$I$3:$I$502,Trade_Reports!$H$3:$H$502,$A30,Trade_Reports!$M$3:$M$502,"APPROVED",Trade_Reports!$Q$3:$Q$502,"<="&Settings!$B$4),""))) | I30: =IF($A30="","",IF($F30="","",IF($Q30="","",IF(ABS($F30-$Q30)/$Q30<=Settings!$B$18,"STABLE",IF($F30>$Q30,"UP","DOWN"))))) | J30: =IF($A30="","",IF($K30=0,"",MIN(1,ROUND($K30/Settings!$B$14,2)))) | K30: =IF($A30="","",COUNTIFS(Trade_Reports!$H$3:$H$502,$A30,Trade_Reports!$M$3:$M$502,"APPROVED",Trade_Reports!$Q$3:$Q$502,"<="&Settings!$B$4)) | L30: =IF($A30="","",IF($K30=0,"",IFERROR(_xludf.MAXIFS(Trade_Reports!$O$3:$O$502,Trade_Reports!$H$3:$H$502,$A30,Trade_Reports!$M$3:$M$502,"APPROVED"),""))) | M30: NO | O30: =IF(OR($A30="",ISERROR(SEARCH("_",$A30))),"", $W30) | P30: =IF($A30="","",SUMIFS(Trade_Reports!$U$3:$U$502,Trade_Reports!$H$3:$H$502,$A30,Trade_Reports!$M$3:$M$502,"APPROVED",Trade_Reports!$Q$3:$Q$502,"<="&Settings!$B$4)) | Q30: =IF($A30="","",SUMIFS(Trade_Reports!$U$3:$U$502,Trade_Reports!$H$3:$H$502,$A30,Trade_Reports!$M$3:$M$502,"APPROVED",Trade_Reports!$Q$3:$Q$502,"<="&Settings!$B$5)) | R30: =IF($A30="","",IF($Q30=0,"",IFERROR(_xludf.MINIFS(Trade_Reports!$I$3:$I$502,Trade_Reports!$H$3:$H$502,$A30,Trade_Reports!$M$3:$M$502,"APPROVED",Trade_Reports!$Q$3:$Q$502,"<="&Settings!$B$5,Trade_Reports!$X$3:$X$502,">="&0.5*$Q30),""))) | S30: =IF($A30="","",COUNTIFS(Trade_Reports!$H$3:$H$502,$A30,Trade_Reports!$M$3:$M$502,"APPROVED",Trade_Reports!$Q$3:$Q$502,"<="&Settings!$B$5)) | V30: =IF(OR($A30="",ISERROR(SEARCH("_",$A30))),"",IFERROR(SUMIFS(Trade_Reports!$Z$3:$Z$502,Trade_Reports!$H$3:$H$502,$A30,Trade_Reports!$M$3:$M$502,"APPROVED")/SUMIFS(Trade_Reports!$U$3:$U$502,Trade_Reports!$H$3:$H$502,$A30,Trade_Reports!$M$3:$M$502,"APPROVED"),"")) | W30: =IF($V30="","",IF($V30<1.75,"LOW",IF($V30<2.5,"MID","HIGH")))
F31: =IF($A31="","",IF($K31<Settings!$B$14,"",IF($P31=0,"",IFERROR(_xludf.MINIFS(Trade_Reports!$I$3:$I$502,Trade_Reports!$H$3:$H$502,$A31,Trade_Reports!$M$3:$M$502,"APPROVED",Trade_Reports!$Q$3:$Q$502,"<="&Settings!$B$4,Trade_Reports!$W$3:$W$502,">="&0.5*$P31),"")))) | G31: =IF($A31="","",IF($K31=0,"",IFERROR(_xludf.MINIFS(Trade_Reports!$I$3:$I$502,Trade_Reports!$H$3:$H$502,$A31,Trade_Reports!$M$3:$M$502,"APPROVED",Trade_Reports!$Q$3:$Q$502,"<="&Settings!$B$4),""))) | H31: =IF($A31="","",IF($K31=0,"",IFERROR(_xludf.MAXIFS(Trade_Reports!$I$3:$I$502,Trade_Reports!$H$3:$H$502,$A31,Trade_Reports!$M$3:$M$502,"APPROVED",Trade_Reports!$Q$3:$Q$502,"<="&Settings!$B$4),""))) | I31: =IF($A31="","",IF($F31="","",IF($Q31="","",IF(ABS($F31-$Q31)/$Q31<=Settings!$B$18,"STABLE",IF($F31>$Q31,"UP","DOWN"))))) | J31: =IF($A31="","",IF($K31=0,"",MIN(1,ROUND($K31/Settings!$B$14,2)))) | K31: =IF($A31="","",COUNTIFS(Trade_Reports!$H$3:$H$502,$A31,Trade_Reports!$M$3:$M$502,"APPROVED",Trade_Reports!$Q$3:$Q$502,"<="&Settings!$B$4)) | L31: =IF($A31="","",IF($K31=0,"",IFERROR(_xludf.MAXIFS(Trade_Reports!$O$3:$O$502,Trade_Reports!$H$3:$H$502,$A31,Trade_Reports!$M$3:$M$502,"APPROVED"),""))) | M31: NO | O31: =IF(OR($A31="",ISERROR(SEARCH("_",$A31))),"", $W31) | P31: =IF($A31="","",SUMIFS(Trade_Reports!$U$3:$U$502,Trade_Reports!$H$3:$H$502,$A31,Trade_Reports!$M$3:$M$502,"APPROVED",Trade_Reports!$Q$3:$Q$502,"<="&Settings!$B$4)) | Q31: =IF($A31="","",SUMIFS(Trade_Reports!$U$3:$U$502,Trade_Reports!$H$3:$H$502,$A31,Trade_Reports!$M$3:$M$502,"APPROVED",Trade_Reports!$Q$3:$Q$502,"<="&Settings!$B$5)) | R31: =IF($A31="","",IF($Q31=0,"",IFERROR(_xludf.MINIFS(Trade_Reports!$I$3:$I$502,Trade_Reports!$H$3:$H$502,$A31,Trade_Reports!$M$3:$M$502,"APPROVED",Trade_Reports!$Q$3:$Q$502,"<="&Settings!$B$5,Trade_Reports!$X$3:$X$502,">="&0.5*$Q31),""))) | S31: =IF($A31="","",COUNTIFS(Trade_Reports!$H$3:$H$502,$A31,Trade_Reports!$M$3:$M$502,"APPROVED",Trade_Reports!$Q$3:$Q$502,"<="&Settings!$B$5)) | V31: =IF(OR($A31="",ISERROR(SEARCH("_",$A31))),"",IFERROR(SUMIFS(Trade_Reports!$Z$3:$Z$502,Trade_Reports!$H$3:$H$502,$A31,Trade_Reports!$M$3:$M$502,"APPROVED")/SUMIFS(Trade_Reports!$U$3:$U$502,Trade_Reports!$H$3:$H$502,$A31,Trade_Reports!$M$3:$M$502,"APPROVED"),"")) | W31: =IF($V31="","",IF($V31<1.75,"LOW",IF($V31<2.5,"MID","HIGH")))
F32: =IF($A32="","",IF($K32<Settings!$B$14,"",IF($P32=0,"",IFERROR(_xludf.MINIFS(Trade_Reports!$I$3:$I$502,Trade_Reports!$H$3:$H$502,$A32,Trade_Reports!$M$3:$M$502,"APPROVED",Trade_Reports!$Q$3:$Q$502,"<="&Settings!$B$4,Trade_Reports!$W$3:$W$502,">="&0.5*$P32),"")))) | G32: =IF($A32="","",IF($K32=0,"",IFERROR(_xludf.MINIFS(Trade_Reports!$I$3:$I$502,Trade_Reports!$H$3:$H$502,$A32,Trade_Reports!$M$3:$M$502,"APPROVED",Trade_Reports!$Q$3:$Q$502,"<="&Settings!$B$4),""))) | H32: =IF($A32="","",IF($K32=0,"",IFERROR(_xludf.MAXIFS(Trade_Reports!$I$3:$I$502,Trade_Reports!$H$3:$H$502,$A32,Trade_Reports!$M$3:$M$502,"APPROVED",Trade_Reports!$Q$3:$Q$502,"<="&Settings!$B$4),""))) | I32: =IF($A32="","",IF($F32="","",IF($Q32="","",IF(ABS($F32-$Q32)/$Q32<=Settings!$B$18,"STABLE",IF($F32>$Q32,"UP","DOWN"))))) | J32: =IF($A32="","",IF($K32=0,"",MIN(1,ROUND($K32/Settings!$B$14,2)))) | K32: =IF($A32="","",COUNTIFS(Trade_Reports!$H$3:$H$502,$A32,Trade_Reports!$M$3:$M$502,"APPROVED",Trade_Reports!$Q$3:$Q$502,"<="&Settings!$B$4)) | L32: =IF($A32="","",IF($K32=0,"",IFERROR(_xludf.MAXIFS(Trade_Reports!$O$3:$O$502,Trade_Reports!$H$3:$H$502,$A32,Trade_Reports!$M$3:$M$502,"APPROVED"),""))) | M32: NO | O32: =IF(OR($A32="",ISERROR(SEARCH("_",$A32))),"", $W32) | P32: =IF($A32="","",SUMIFS(Trade_Reports!$U$3:$U$502,Trade_Reports!$H$3:$H$502,$A32,Trade_Reports!$M$3:$M$502,"APPROVED",Trade_Reports!$Q$3:$Q$502,"<="&Settings!$B$4)) | Q32: =IF($A32="","",SUMIFS(Trade_Reports!$U$3:$U$502,Trade_Reports!$H$3:$H$502,$A32,Trade_Reports!$M$3:$M$502,"APPROVED",Trade_Reports!$Q$3:$Q$502,"<="&Settings!$B$5)) | R32: =IF($A32="","",IF($Q32=0,"",IFERROR(_xludf.MINIFS(Trade_Reports!$I$3:$I$502,Trade_Reports!$H$3:$H$502,$A32,Trade_Reports!$M$3:$M$502,"APPROVED",Trade_Reports!$Q$3:$Q$502,"<="&Settings!$B$5,Trade_Reports!$X$3:$X$502,">="&0.5*$Q32),""))) | S32: =IF($A32="","",COUNTIFS(Trade_Reports!$H$3:$H$502,$A32,Trade_Reports!$M$3:$M$502,"APPROVED",Trade_Reports!$Q$3:$Q$502,"<="&Settings!$B$5)) | V32: =IF(OR($A32="",ISERROR(SEARCH("_",$A32))),"",IFERROR(SUMIFS(Trade_Reports!$Z$3:$Z$502,Trade_Reports!$H$3:$H$502,$A32,Trade_Reports!$M$3:$M$502,"APPROVED")/SUMIFS(Trade_Reports!$U$3:$U$502,Trade_Reports!$H$3:$H$502,$A32,Trade_Reports!$M$3:$M$502,"APPROVED"),"")) | W32: =IF($V32="","",IF($V32<1.75,"LOW",IF($V32<2.5,"MID","HIGH")))
F33: =IF($A33="","",IF($K33<Settings!$B$14,"",IF($P33=0,"",IFERROR(_xludf.MINIFS(Trade_Reports!$I$3:$I$502,Trade_Reports!$H$3:$H$502,$A33,Trade_Reports!$M$3:$M$502,"APPROVED",Trade_Reports!$Q$3:$Q$502,"<="&Settings!$B$4,Trade_Reports!$W$3:$W$502,">="&0.5*$P33),"")))) | G33: =IF($A33="","",IF($K33=0,"",IFERROR(_xludf.MINIFS(Trade_Reports!$I$3:$I$502,Trade_Reports!$H$3:$H$502,$A33,Trade_Reports!$M$3:$M$502,"APPROVED",Trade_Reports!$Q$3:$Q$502,"<="&Settings!$B$4),""))) | H33: =IF($A33="","",IF($K33=0,"",IFERROR(_xludf.MAXIFS(Trade_Reports!$I$3:$I$502,Trade_Reports!$H$3:$H$502,$A33,Trade_Reports!$M$3:$M$502,"APPROVED",Trade_Reports!$Q$3:$Q$502,"<="&Settings!$B$4),""))) | I33: =IF($A33="","",IF($F33="","",IF($Q33="","",IF(ABS($F33-$Q33)/$Q33<=Settings!$B$18,"STABLE",IF($F33>$Q33,"UP","DOWN"))))) | J33: =IF($A33="","",IF($K33=0,"",MIN(1,ROUND($K33/Settings!$B$14,2)))) | K33: =IF($A33="","",COUNTIFS(Trade_Reports!$H$3:$H$502,$A33,Trade_Reports!$M$3:$M$502,"APPROVED",Trade_Reports!$Q$3:$Q$502,"<="&Settings!$B$4)) | L33: =IF($A33="","",IF($K33=0,"",IFERROR(_xludf.MAXIFS(Trade_Reports!$O$3:$O$502,Trade_Reports!$H$3:$H$502,$A33,Trade_Reports!$M$3:$M$502,"APPROVED"),""))) | M33: NO | O33: =IF(OR($A33="",ISERROR(SEARCH("_",$A33))),"", $W33) | P33: =IF($A33="","",SUMIFS(Trade_Reports!$U$3:$U$502,Trade_Reports!$H$3:$H$502,$A33,Trade_Reports!$M$3:$M$502,"APPROVED",Trade_Reports!$Q$3:$Q$502,"<="&Settings!$B$4)) | Q33: =IF($A33="","",SUMIFS(Trade_Reports!$U$3:$U$502,Trade_Reports!$H$3:$H$502,$A33,Trade_Reports!$M$3:$M$502,"APPROVED",Trade_Reports!$Q$3:$Q$502,"<="&Settings!$B$5)) | R33: =IF($A33="","",IF($Q33=0,"",IFERROR(_xludf.MINIFS(Trade_Reports!$I$3:$I$502,Trade_Reports!$H$3:$H$502,$A33,Trade_Reports!$M$3:$M$502,"APPROVED",Trade_Reports!$Q$3:$Q$502,"<="&Settings!$B$5,Trade_Reports!$X$3:$X$502,">="&0.5*$Q33),""))) | S33: =IF($A33="","",COUNTIFS(Trade_Reports!$H$3:$H$502,$A33,Trade_Reports!$M$3:$M$502,"APPROVED",Trade_Reports!$Q$3:$Q$502,"<="&Settings!$B$5)) | V33: =IF(OR($A33="",ISERROR(SEARCH("_",$A33))),"",IFERROR(SUMIFS(Trade_Reports!$Z$3:$Z$502,Trade_Reports!$H$3:$H$502,$A33,Trade_Reports!$M$3:$M$502,"APPROVED")/SUMIFS(Trade_Reports!$U$3:$U$502,Trade_Reports!$H$3:$H$502,$A33,Trade_Reports!$M$3:$M$502,"APPROVED"),"")) | W33: =IF($V33="","",IF($V33<1.75,"LOW",IF($V33<2.5,"MID","HIGH")))
F34: =IF($A34="","",IF($K34<Settings!$B$14,"",IF($P34=0,"",IFERROR(_xludf.MINIFS(Trade_Reports!$I$3:$I$502,Trade_Reports!$H$3:$H$502,$A34,Trade_Reports!$M$3:$M$502,"APPROVED",Trade_Reports!$Q$3:$Q$502,"<="&Settings!$B$4,Trade_Reports!$W$3:$W$502,">="&0.5*$P34),"")))) | G34: =IF($A34="","",IF($K34=0,"",IFERROR(_xludf.MINIFS(Trade_Reports!$I$3:$I$502,Trade_Reports!$H$3:$H$502,$A34,Trade_Reports!$M$3:$M$502,"APPROVED",Trade_Reports!$Q$3:$Q$502,"<="&Settings!$B$4),""))) | H34: =IF($A34="","",IF($K34=0,"",IFERROR(_xludf.MAXIFS(Trade_Reports!$I$3:$I$502,Trade_Reports!$H$3:$H$502,$A34,Trade_Reports!$M$3:$M$502,"APPROVED",Trade_Reports!$Q$3:$Q$502,"<="&Settings!$B$4),""))) | I34: =IF($A34="","",IF($F34="","",IF($Q34="","",IF(ABS($F34-$Q34)/$Q34<=Settings!$B$18,"STABLE",IF($F34>$Q34,"UP","DOWN"))))) | J34: =IF($A34="","",IF($K34=0,"",MIN(1,ROUND($K34/Settings!$B$14,2)))) | K34: =IF($A34="","",COUNTIFS(Trade_Reports!$H$3:$H$502,$A34,Trade_Reports!$M$3:$M$502,"APPROVED",Trade_Reports!$Q$3:$Q$502,"<="&Settings!$B$4)) | L34: =IF($A34="","",IF($K34=0,"",IFERROR(_xludf.MAXIFS(Trade_Reports!$O$3:$O$502,Trade_Reports!$H$3:$H$502,$A34,Trade_Reports!$M$3:$M$502,"APPROVED"),""))) | M34: NO | O34: =IF(OR($A34="",ISERROR(SEARCH("_",$A34))),"", $W34) | P34: =IF($A34="","",SUMIFS(Trade_Reports!$U$3:$U$502,Trade_Reports!$H$3:$H$502,$A34,Trade_Reports!$M$3:$M$502,"APPROVED",Trade_Reports!$Q$3:$Q$502,"<="&Settings!$B$4)) | Q34: =IF($A34="","",SUMIFS(Trade_Reports!$U$3:$U$502,Trade_Reports!$H$3:$H$502,$A34,Trade_Reports!$M$3:$M$502,"APPROVED",Trade_Reports!$Q$3:$Q$502,"<="&Settings!$B$5)) | R34: =IF($A34="","",IF($Q34=0,"",IFERROR(_xludf.MINIFS(Trade_Reports!$I$3:$I$502,Trade_Reports!$H$3:$H$502,$A34,Trade_Reports!$M$3:$M$502,"APPROVED",Trade_Reports!$Q$3:$Q$502,"<="&Settings!$B$5,Trade_Reports!$X$3:$X$502,">="&0.5*$Q34),""))) | S34: =IF($A34="","",COUNTIFS(Trade_Reports!$H$3:$H$502,$A34,Trade_Reports!$M$3:$M$502,"APPROVED",Trade_Reports!$Q$3:$Q$502,"<="&Settings!$B$5)) | V34: =IF(OR($A34="",ISERROR(SEARCH("_",$A34))),"",IFERROR(SUMIFS(Trade_Reports!$Z$3:$Z$502,Trade_Reports!$H$3:$H$502,$A34,Trade_Reports!$M$3:$M$502,"APPROVED")/SUMIFS(Trade_Reports!$U$3:$U$502,Trade_Reports!$H$3:$H$502,$A34,Trade_Reports!$M$3:$M$502,"APPROVED"),"")) | W34: =IF($V34="","",IF($V34<1.75,"LOW",IF($V34<2.5,"MID","HIGH")))
F35: =IF($A35="","",IF($K35<Settings!$B$14,"",IF($P35=0,"",IFERROR(_xludf.MINIFS(Trade_Reports!$I$3:$I$502,Trade_Reports!$H$3:$H$502,$A35,Trade_Reports!$M$3:$M$502,"APPROVED",Trade_Reports!$Q$3:$Q$502,"<="&Settings!$B$4,Trade_Reports!$W$3:$W$502,">="&0.5*$P35),"")))) | G35: =IF($A35="","",IF($K35=0,"",IFERROR(_xludf.MINIFS(Trade_Reports!$I$3:$I$502,Trade_Reports!$H$3:$H$502,$A35,Trade_Reports!$M$3:$M$502,"APPROVED",Trade_Reports!$Q$3:$Q$502,"<="&Settings!$B$4),""))) | H35: =IF($A35="","",IF($K35=0,"",IFERROR(_xludf.MAXIFS(Trade_Reports!$I$3:$I$502,Trade_Reports!$H$3:$H$502,$A35,Trade_Reports!$M$3:$M$502,"APPROVED",Trade_Reports!$Q$3:$Q$502,"<="&Settings!$B$4),""))) | I35: =IF($A35="","",IF($F35="","",IF($Q35="","",IF(ABS($F35-$Q35)/$Q35<=Settings!$B$18,"STABLE",IF($F35>$Q35,"UP","DOWN"))))) | J35: =IF($A35="","",IF($K35=0,"",MIN(1,ROUND($K35/Settings!$B$14,2)))) | K35: =IF($A35="","",COUNTIFS(Trade_Reports!$H$3:$H$502,$A35,Trade_Reports!$M$3:$M$502,"APPROVED",Trade_Reports!$Q$3:$Q$502,"<="&Settings!$B$4)) | L35: =IF($A35="","",IF($K35=0,"",IFERROR(_xludf.MAXIFS(Trade_Reports!$O$3:$O$502,Trade_Reports!$H$3:$H$502,$A35,Trade_Reports!$M$3:$M$502,"APPROVED"),""))) | M35: NO | O35: =IF(OR($A35="",ISERROR(SEARCH("_",$A35))),"", $W35) | P35: =IF($A35="","",SUMIFS(Trade_Reports!$U$3:$U$502,Trade_Reports!$H$3:$H$502,$A35,Trade_Reports!$M$3:$M$502,"APPROVED",Trade_Reports!$Q$3:$Q$502,"<="&Settings!$B$4)) | Q35: =IF($A35="","",SUMIFS(Trade_Reports!$U$3:$U$502,Trade_Reports!$H$3:$H$502,$A35,Trade_Reports!$M$3:$M$502,"APPROVED",Trade_Reports!$Q$3:$Q$502,"<="&Settings!$B$5)) | R35: =IF($A35="","",IF($Q35=0,"",IFERROR(_xludf.MINIFS(Trade_Reports!$I$3:$I$502,Trade_Reports!$H$3:$H$502,$A35,Trade_Reports!$M$3:$M$502,"APPROVED",Trade_Reports!$Q$3:$Q$502,"<="&Settings!$B$5,Trade_Reports!$X$3:$X$502,">="&0.5*$Q35),""))) | S35: =IF($A35="","",COUNTIFS(Trade_Reports!$H$3:$H$502,$A35,Trade_Reports!$M$3:$M$502,"APPROVED",Trade_Reports!$Q$3:$Q$502,"<="&Settings!$B$5)) | V35: =IF(OR($A35="",ISERROR(SEARCH("_",$A35))),"",IFERROR(SUMIFS(Trade_Reports!$Z$3:$Z$502,Trade_Reports!$H$3:$H$502,$A35,Trade_Reports!$M$3:$M$502,"APPROVED")/SUMIFS(Trade_Reports!$U$3:$U$502,Trade_Reports!$H$3:$H$502,$A35,Trade_Reports!$M$3:$M$502,"APPROVED"),"")) | W35: =IF($V35="","",IF($V35<1.75,"LOW",IF($V35<2.5,"MID","HIGH")))
F36: =IF($A36="","",IF($K36<Settings!$B$14,"",IF($P36=0,"",IFERROR(_xludf.MINIFS(Trade_Reports!$I$3:$I$502,Trade_Reports!$H$3:$H$502,$A36,Trade_Reports!$M$3:$M$502,"APPROVED",Trade_Reports!$Q$3:$Q$502,"<="&Settings!$B$4,Trade_Reports!$W$3:$W$502,">="&0.5*$P36),"")))) | G36: =IF($A36="","",IF($K36=0,"",IFERROR(_xludf.MINIFS(Trade_Reports!$I$3:$I$502,Trade_Reports!$H$3:$H$502,$A36,Trade_Reports!$M$3:$M$502,"APPROVED",Trade_Reports!$Q$3:$Q$502,"<="&Settings!$B$4),""))) | H36: =IF($A36="","",IF($K36=0,"",IFERROR(_xludf.MAXIFS(Trade_Reports!$I$3:$I$502,Trade_Reports!$H$3:$H$502,$A36,Trade_Reports!$M$3:$M$502,"APPROVED",Trade_Reports!$Q$3:$Q$502,"<="&Settings!$B$4),""))) | I36: =IF($A36="","",IF($F36="","",IF($Q36="","",IF(ABS($F36-$Q36)/$Q36<=Settings!$B$18,"STABLE",IF($F36>$Q36,"UP","DOWN"))))) | J36: =IF($A36="","",IF($K36=0,"",MIN(1,ROUND($K36/Settings!$B$14,2)))) | K36: =IF($A36="","",COUNTIFS(Trade_Reports!$H$3:$H$502,$A36,Trade_Reports!$M$3:$M$502,"APPROVED",Trade_Reports!$Q$3:$Q$502,"<="&Settings!$B$4)) | L36: =IF($A36="","",IF($K36=0,"",IFERROR(_xludf.MAXIFS(Trade_Reports!$O$3:$O$502,Trade_Reports!$H$3:$H$502,$A36,Trade_Reports!$M$3:$M$502,"APPROVED"),""))) | M36: NO | O36: =IF(OR($A36="",ISERROR(SEARCH("_",$A36))),"", $W36) | P36: =IF($A36="","",SUMIFS(Trade_Reports!$U$3:$U$502,Trade_Reports!$H$3:$H$502,$A36,Trade_Reports!$M$3:$M$502,"APPROVED",Trade_Reports!$Q$3:$Q$502,"<="&Settings!$B$4)) | Q36: =IF($A36="","",SUMIFS(Trade_Reports!$U$3:$U$502,Trade_Reports!$H$3:$H$502,$A36,Trade_Reports!$M$3:$M$502,"APPROVED",Trade_Reports!$Q$3:$Q$502,"<="&Settings!$B$5)) | R36: =IF($A36="","",IF($Q36=0,"",IFERROR(_xludf.MINIFS(Trade_Reports!$I$3:$I$502,Trade_Reports!$H$3:$H$502,$A36,Trade_Reports!$M$3:$M$502,"APPROVED",Trade_Reports!$Q$3:$Q$502,"<="&Settings!$B$5,Trade_Reports!$X$3:$X$502,">="&0.5*$Q36),""))) | S36: =IF($A36="","",COUNTIFS(Trade_Reports!$H$3:$H$502,$A36,Trade_Reports!$M$3:$M$502,"APPROVED",Trade_Reports!$Q$3:$Q$502,"<="&Settings!$B$5)) | V36: =IF(OR($A36="",ISERROR(SEARCH("_",$A36))),"",IFERROR(SUMIFS(Trade_Reports!$Z$3:$Z$502,Trade_Reports!$H$3:$H$502,$A36,Trade_Reports!$M$3:$M$502,"APPROVED")/SUMIFS(Trade_Reports!$U$3:$U$502,Trade_Reports!$H$3:$H$502,$A36,Trade_Reports!$M$3:$M$502,"APPROVED"),"")) | W36: =IF($V36="","",IF($V36<1.75,"LOW",IF($V36<2.5,"MID","HIGH")))
F37: =IF($A37="","",IF($K37<Settings!$B$14,"",IF($P37=0,"",IFERROR(_xludf.MINIFS(Trade_Reports!$I$3:$I$502,Trade_Reports!$H$3:$H$502,$A37,Trade_Reports!$M$3:$M$502,"APPROVED",Trade_Reports!$Q$3:$Q$502,"<="&Settings!$B$4,Trade_Reports!$W$3:$W$502,">="&0.5*$P37),"")))) | G37: =IF($A37="","",IF($K37=0,"",IFERROR(_xludf.MINIFS(Trade_Reports!$I$3:$I$502,Trade_Reports!$H$3:$H$502,$A37,Trade_Reports!$M$3:$M$502,"APPROVED",Trade_Reports!$Q$3:$Q$502,"<="&Settings!$B$4),""))) | H37: =IF($A37="","",IF($K37=0,"",IFERROR(_xludf.MAXIFS(Trade_Reports!$I$3:$I$502,Trade_Reports!$H$3:$H$502,$A37,Trade_Reports!$M$3:$M$502,"APPROVED",Trade_Reports!$Q$3:$Q$502,"<="&Settings!$B$4),""))) | I37: =IF($A37="","",IF($F37="","",IF($Q37="","",IF(ABS($F37-$Q37)/$Q37<=Settings!$B$18,"STABLE",IF($F37>$Q37,"UP","DOWN"))))) | J37: =IF($A37="","",IF($K37=0,"",MIN(1,ROUND($K37/Settings!$B$14,2)))) | K37: =IF($A37="","",COUNTIFS(Trade_Reports!$H$3:$H$502,$A37,Trade_Reports!$M$3:$M$502,"APPROVED",Trade_Reports!$Q$3:$Q$502,"<="&Settings!$B$4)) | L37: =IF($A37="","",IF($K37=0,"",IFERROR(_xludf.MAXIFS(Trade_Reports!$O$3:$O$502,Trade_Reports!$H$3:$H$502,$A37,Trade_Reports!$M$3:$M$502,"APPROVED"),""))) | M37: NO | O37: =IF(OR($A37="",ISERROR(SEARCH("_",$A37))),"", $W37) | P37: =IF($A37="","",SUMIFS(Trade_Reports!$U$3:$U$502,Trade_Reports!$H$3:$H$502,$A37,Trade_Reports!$M$3:$M$502,"APPROVED",Trade_Reports!$Q$3:$Q$502,"<="&Settings!$B$4)) | Q37: =IF($A37="","",SUMIFS(Trade_Reports!$U$3:$U$502,Trade_Reports!$H$3:$H$502,$A37,Trade_Reports!$M$3:$M$502,"APPROVED",Trade_Reports!$Q$3:$Q$502,"<="&Settings!$B$5)) | R37: =IF($A37="","",IF($Q37=0,"",IFERROR(_xludf.MINIFS(Trade_Reports!$I$3:$I$502,Trade_Reports!$H$3:$H$502,$A37,Trade_Reports!$M$3:$M$502,"APPROVED",Trade_Reports!$Q$3:$Q$502,"<="&Settings!$B$5,Trade_Reports!$X$3:$X$502,">="&0.5*$Q37),""))) | S37: =IF($A37="","",COUNTIFS(Trade_Reports!$H$3:$H$502,$A37,Trade_Reports!$M$3:$M$502,"APPROVED",Trade_Reports!$Q$3:$Q$502,"<="&Settings!$B$5)) | V37: =IF(OR($A37="",ISERROR(SEARCH("_",$A37))),"",IFERROR(SUMIFS(Trade_Reports!$Z$3:$Z$502,Trade_Reports!$H$3:$H$502,$A37,Trade_Reports!$M$3:$M$502,"APPROVED")/SUMIFS(Trade_Reports!$U$3:$U$502,Trade_Reports!$H$3:$H$502,$A37,Trade_Reports!$M$3:$M$502,"APPROVED"),"")) | W37: =IF($V37="","",IF($V37<1.75,"LOW",IF($V37<2.5,"MID","HIGH")))
